Workbook

Sheet Cómo usar
A1: Tracker: 50 empresas – oposición y supresión de datos + No Molestar
A3: 1. En 'Empresas', mira la columna 'Vía de envío': Correo = manda la plantilla al correo indicado; Formulario web = usa el link; Canal alternativo = la empresa no publica correo de datos personales, usa el teléfono, sucursal o formulario indicado.
A4: 2. Envía el correo de la plantilla (documento aparte) a cada empresa y anota la fecha en 'Enviado (fecha)'.
A5: 3. Ingresa la solicitud No Molestar en el Portal del Consumidor del SERNAC (con tu ClaveÚnica) y anota fecha y N°.
A6: 4. Los plazos se calculan solos en días hábiles, descontando fines de semana y los feriados de la hoja 'Feriados'.
A7: 5. Si siguen llamando después del plazo, marca 'Sí' en '¿Siguen llamando?' y presenta el aviso de incumplimiento en el portal.
A9: Celdas amarillas = las llenas tú. Celdas blancas = datos investigados o fórmulas (no editar).
A10: Plazo respuesta correo: 2 días hábiles (art. 16, Ley 19.628). Plazo No Molestar: 7 días hábiles (SERNAC).
A11: Lista armada a partir de los rankings públicos del SERNAC (Claro-VTR, Movistar, Entel, WOM encabezan desde 2019) y de los sectores que concentran las solicitudes: telecom, financiero, retail y seguros. El SERNAC no publica un top 50 oficial.
A12: Feriados: verificar contra la lista oficial cada año. Esto no es asesoría legal.

Sheet Empresas
A1: # | B1: Marca | C1: Sector | D1: Razón social | E1: RUT | F1: Correo datos personales | G1: Formulario web | H1: Opt-out propio | I1: Canal alternativo | J1: Fuente | K1: Vía de envío | L1: Enviado (fecha) | M1: Plazo respuesta correo | N1: ¿Respondió? | O1: No Molestar ingresado | P1: N° solicitud SERNAC | Q1: Plazo No Molestar | R1: ¿Siguen llamando? | S1: Aviso incumplimiento | T1: Estado | U1: Notas
A2: 1 | B2: Claro Chile | C2: Telecom | F2: datos.personales@clarochile.cl | G2: https://denuncias.americamovil.com/ | H2: Formulario 'No Molestar' en el sitio de Claro (efecto inmediato para comunicaciones publicitarias); política 2022 enlaza https://www.clarochile.cl/portal/cl/legal-regulatorio/lightbox/descripcion-ED-209.html para dejar de recibir ofertas; también derecho art. 28B Ley 19.496 | I2: Centros de Atención Claro VTR (presencial) / call center | J2: https://www.clarochile.cl/portal/cl/recursos_contenido/pdf/1738265380882-politica-de-proteccion-de-datos-personalesclarovtr-2025.pdf | K2: Correo | M2: =IF(L2="","",WORKDAY(L2,2,Feriados!$A$2:$A$60)) | Q2: =IF(O2="","",WORKDAY(O2,7,Feriados!$A$2:$A$60)) | T2: =IF(AND(L2="",O2=""),"Por enviar",IF(R2="Sí",IF(S2="","Reportar incumplimiento","Incumplimiento reportado"),IF(AND(Q2<>"",TODAY()>Q2),"Plazo vencido – verificar",IF(AND(M2<>"",TODAY()>M2,N2<>"Sí"),"Correo sin respuesta","En plazo"))))
A3: 2 | B3: VTR | C3: Telecom | F3: datos.personales@clarochile.cl | G3: https://denuncias.americamovil.com/ | H3: Formulario 'VTR: No Molestar' referido en la política conjunta Claro VTR | I3: Centros de Atención Claro VTR / centrodeayudaonline.vtr.com | J3: https://www.clarochile.cl/portal/cl/recursos_contenido/pdf/1738265380882-politica-de-proteccion-de-datos-personalesclarovtr-2025.pdf | K3: Correo | M3: =IF(L3="","",WORKDAY(L3,2,Feriados!$A$2:$A$60)) | Q3: =IF(O3="","",WORKDAY(O3,7,Feriados!$A$2:$A$60)) | T3: =IF(AND(L3="",O3=""),"Por enviar",IF(R3="Sí",IF(S3="","Reportar incumplimiento","Incumplimiento reportado"),IF(AND(Q3<>"",TODAY()>Q3),"Plazo vencido – verificar",IF(AND(M3<>"",TODAY()>M3,N3<>"Sí"),"Correo sin respuesta","En plazo"))))
A4: 3 | B4: Movistar Chile (Telefónica Chile) | C4: Telecom | G4: https://legalmovistar.mvch.cl/ | H4: Formulario No Molestar (llamadas, SMS, WhatsApp, email; art. 28B Ley 19.496): https://catalogo.movistar.cl/planes/formularionomolestar ; link de des-inscripción en cada email | I4: Teléfono 103, sucursales Movistar, redes sociales; Oficina de Protección de Datos de Movistar Chile | J4: https://ww2.movistar.cl/centro-de-transparencia/derechos.html | K4: Formulario web | M4: =IF(L4="","",WORKDAY(L4,2,Feriados!$A$2:$A$60)) | Q4: =IF(O4="","",WORKDAY(O4,7,Feriados!$A$2:$A$60)) | T4: =IF(AND(L4="",O4=""),"Por enviar",IF(R4="Sí",IF(S4="","Reportar incumplimiento","Incumplimiento reportado"),IF(AND(Q4<>"",TODAY()>Q4),"Plazo vencido – verificar",IF(AND(M4<>"",TODAY()>M4,N4<>"Sí"),"Correo sin respuesta","En plazo"))))
A5: 4 | B5: Entel | C5: Telecom | D5: Empresa Nacional de Telecomunicaciones S.A. / Entel PCS Telecomunicaciones S.A. | E5: 92.580.000-7 / 96.806.980-2 | F5: protecciondedatos@entel.cl | H5: Oposición a comunicaciones comerciales por cada canal, siguiendo instrucciones incluidas en cada mensaje | I5: Mi Entel (web), App Entel, sucursales Entel, call center | J5: https://entelconviene.entel.cl/media/entelconviene/terminosCondiciones/Politica-Privacidad-Clientes-Nov-2022.pdf | K5: Correo | M5: =IF(L5="","",WORKDAY(L5,2,Feriados!$A$2:$A$60)) | Q5: =IF(O5="","",WORKDAY(O5,7,Feriados!$A$2:$A$60)) | T5: =IF(AND(L5="",O5=""),"Por enviar",IF(R5="Sí",IF(S5="","Reportar incumplimiento","Incumplimiento reportado"),IF(AND(Q5<>"",TODAY()>Q5),"Plazo vencido – verificar",IF(AND(M5<>"",TODAY()>M5,N5<>"Sí"),"Correo sin respuesta","En plazo"))))
A6: 5 | B6: WOM Chile | C6: Telecom | H6: Artículo de ayuda 'No molestar WOM': https://www.wom.cl/centro-de-ayuda/como-puedo-dejar-de-recibir-informacion-de-wom/ (contenido no verificado) | I6: Centro de ayuda WOM: https://www.wom.cl/centro-de-ayuda/ | J6: https://www.wom.cl/politica-privacidad/ | K6: Canal alternativo | M6: =IF(L6="","",WORKDAY(L6,2,Feriados!$A$2:$A$60)) | Q6: =IF(O6="","",WORKDAY(O6,7,Feriados!$A$2:$A$60)) | T6: =IF(AND(L6="",O6=""),"Por enviar",IF(R6="Sí",IF(S6="","Reportar incumplimiento","Incumplimiento reportado"),IF(AND(Q6<>"",TODAY()>Q6),"Plazo vencido – verificar",IF(AND(M6<>"",TODAY()>M6,N6<>"Sí"),"Correo sin respuesta","En plazo"))))
A7: 6 | B7: Mundo Telecomunicaciones (mundo.cl) | C7: Telecom | D7: Pácifico Cable SpA | E7: 96.722.400-6 | F7: legal@mundotelecomunicaciones.cl | G7: https://www.tumundo.cl/wp-content/uploads/2025/06/FORMULARIO-EJERCICIO-DERECHOS-DATOS-PERSONALES.pdf | H7: Instrucciones de baja en cada mensaje (por canal); registro 'No Molestar' de SERNAC | I7: Call Center 600 9100 100, www.tumundo.cl, sucursales; también ciberseguridad@mundotelecomunicaciones.cl para consultas de la política | J7: https://www.tumundo.cl/wp-content/uploads/2025/06/Politica-de-privacidad-.pdf | K7: Correo | M7: =IF(L7="","",WORKDAY(L7,2,Feriados!$A$2:$A$60)) | Q7: =IF(O7="","",WORKDAY(O7,7,Feriados!$A$2:$A$60)) | T7: =IF(AND(L7="",O7=""),"Por enviar",IF(R7="Sí",IF(S7="","Reportar incumplimiento","Incumplimiento reportado"),IF(AND(Q7<>"",TODAY()>Q7),"Plazo vencido – verificar",IF(AND(M7<>"",TODAY()>M7,N7<>"Sí"),"Correo sin respuesta","En plazo")))) | U7: El correo legal@ es para consultas sobre la política; para ejercer derechos la empresa ofrece el formulario PDF.
A8: 7 | B8: DirecTV Chile | C8: Telecom | I8: Sucursales/atención DIRECTV Chile: https://www.directvla.com/cl/sucursales | J8: https://www.directvla.com/cl/politicas-de-privacidad | K8: Canal alternativo | M8: =IF(L8="","",WORKDAY(L8,2,Feriados!$A$2:$A$60)) | Q8: =IF(O8="","",WORKDAY(O8,7,Feriados!$A$2:$A$60)) | T8: =IF(AND(L8="",O8=""),"Por enviar",IF(R8="Sí",IF(S8="","Reportar incumplimiento","Incumplimiento reportado"),IF(AND(Q8<>"",TODAY()>Q8),"Plazo vencido – verificar",IF(AND(M8<>"",TODAY()>M8,N8<>"Sí"),"Correo sin respuesta","En plazo"))))
A9: 8 | B9: GTD | C9: Telecom | D9: Grupo GTD Teleductos S.A. | E9: 94.727.000-1 | F9: datos.personales@grupogtd.com | H9: Revocación del consentimiento (incl. comunicaciones de marketing) escribiendo a datos.personales@grupogtd.com | I9: Call Center 600 950 5000; WhatsApp +56 9 6761 9001; formulario reclamos https://www.gtd.cl/formulario-reclamos | J9: https://www.gtd.cl/politica-de-privacidad-y-proteccion-de-datos-personales-2026 | K9: Correo | M9: =IF(L9="","",WORKDAY(L9,2,Feriados!$A$2:$A$60)) | Q9: =IF(O9="","",WORKDAY(O9,7,Feriados!$A$2:$A$60)) | T9: =IF(AND(L9="",O9=""),"Por enviar",IF(R9="Sí",IF(S9="","Reportar incumplimiento","Incumplimiento reportado"),IF(AND(Q9<>"",TODAY()>Q9),"Plazo vencido – verificar",IF(AND(M9<>"",TODAY()>M9,N9<>"Sí"),"Correo sin respuesta","En plazo"))))
A10: 9 | B10: Rappi Chile | C10: Otros | D10: Rappi Chile SpA | E10: 76.837.223-3 | F10: notificacioneslegalcl@rappi.com | G10: https://www.rappi.cl/account/profile | H10: Exclusión de listas promocionales por email a servicioalclientechile@rappi.com; preferencias vía link en emails o en la Cuenta; portal No Molestar SERNAC | I10: servicioalclientechile@rappi.com / soporte en la app | J10: https://legal.rappi.com/chile/politica-de-privacidad/ | K10: Correo | M10: =IF(L10="","",WORKDAY(L10,2,Feriados!$A$2:$A$60)) | Q10: =IF(O10="","",WORKDAY(O10,7,Feriados!$A$2:$A$60)) | T10: =IF(AND(L10="",O10=""),"Por enviar",IF(R10="Sí",IF(S10="","Reportar incumplimiento","Incumplimiento reportado"),IF(AND(Q10<>"",TODAY()>Q10),"Plazo vencido – verificar",IF(AND(M10<>"",TODAY()>M10,N10<>"Sí"),"Correo sin respuesta","En plazo"))))
A11: 10 | B11: Mercado Libre / Mercado Pago Chile | C11: Otros | I11: Centro de privacidad / ayuda: https://www.mercadolibre.cl/privacidad | J11: https://www.mercadopago.cl/privacidad/declaracion-privacidad/31199 | K11: Canal alternativo | M11: =IF(L11="","",WORKDAY(L11,2,Feriados!$A$2:$A$60)) | Q11: =IF(O11="","",WORKDAY(O11,7,Feriados!$A$2:$A$60)) | T11: =IF(AND(L11="",O11=""),"Por enviar",IF(R11="Sí",IF(S11="","Reportar incumplimiento","Incumplimiento reportado"),IF(AND(Q11<>"",TODAY()>Q11),"Plazo vencido – verificar",IF(AND(M11<>"",TODAY()>M11,N11<>"Sí"),"Correo sin respuesta","En plazo"))))
A12: 11 | B12: Banco de Chile | C12: Banca | D12: Banco de Chile | E12: 97.004.000-5 | F12: protecciondatos@bancochile.cl | H12: Consent (incl. for commercial/marketing purposes) can be revoked at any time 'por los canales establecidos por el Banco'; policy also refers to a 'Derechos ARCO' channel on the bank website (no direct URL given). Email listed is for the Delegado/Gerente de Protección de Datos. | I12: 'Derechos ARCO' channel on bancochile.cl website | J12: https://sitiospublicos.bancochile.cl/personas/politica-de-privacidad | K12: Correo | M12: =IF(L12="","",WORKDAY(L12,2,Feriados!$A$2:$A$60)) | Q12: =IF(O12="","",WORKDAY(O12,7,Feriados!$A$2:$A$60)) | T12: =IF(AND(L12="",O12=""),"Por enviar",IF(R12="Sí",IF(S12="","Reportar incumplimiento","Incumplimiento reportado"),IF(AND(Q12<>"",TODAY()>Q12),"Plazo vencido – verificar",IF(AND(M12<>"",TODAY()>M12,N12<>"Sí"),"Correo sin respuesta","En plazo"))))
A13: 12 | B13: BancoEstado | C13: Banca | H13: Contract text: authorization may be revoked and rights of acceso, oposición, información, modificación y cancelación exercised at any time at the Servicio de Atención al Cliente in branches or via the bank's contact channels (www.bancoestado.cl or phone 600 200 7000). | I13: Teléfono 600 200 7000; Servicio de Atención al Cliente en sucursales; www.bancoestado.cl | J13: https://www.bancoestado.cl/content/dam/bancoestado-public/pdf/contratos-productos/cuentas/Cuenta_Corriente_Digital.pdf | K13: Canal alternativo | M13: =IF(L13="","",WORKDAY(L13,2,Feriados!$A$2:$A$60)) | Q13: =IF(O13="","",WORKDAY(O13,7,Feriados!$A$2:$A$60)) | T13: =IF(AND(L13="",O13=""),"Por enviar",IF(R13="Sí",IF(S13="","Reportar incumplimiento","Incumplimiento reportado"),IF(AND(Q13<>"",TODAY()>Q13),"Plazo vencido – verificar",IF(AND(M13<>"",TODAY()>M13,N13<>"Sí"),"Correo sin respuesta","En plazo"))))
A14: 13 | B14: Banco Santander Chile | C14: Banca | D14: Banco Santander Chile | E14: 97.036.000-K | F14: derechosarco@santander.cl | H14: Right of opposition (oposición) applies when data are used for commercial communications; exercised by email to derechosarco@santander.cl. | I14: Teléfono 600 320 3000 | J14: https://banco.santander.cl/personas/politica-de-privacidad-portal-santander | K14: Correo | M14: =IF(L14="","",WORKDAY(L14,2,Feriados!$A$2:$A$60)) | Q14: =IF(O14="","",WORKDAY(O14,7,Feriados!$A$2:$A$60)) | T14: =IF(AND(L14="",O14=""),"Por enviar",IF(R14="Sí",IF(S14="","Reportar incumplimiento","Incumplimiento reportado"),IF(AND(Q14<>"",TODAY()>Q14),"Plazo vencido – verificar",IF(AND(M14<>"",TODAY()>M14,N14<>"Sí"),"Correo sin respuesta","En plazo"))))
A15: 14 | B15: Bci | C15: Banca | D15: Banco de Crédito e Inversiones S.A. | E15: 97.006.000-6 | F15: privacidad@bci.cl | H15: Titular may request blocking (bloqueo) of their data if they do not wish to receive direct marketing (per Bci privacy policy); rights under art. 12 Ley 19.628 exercised via privacidad@bci.cl. | I15: Banca Telefónica 600 692 8000; https://www.bci.cl/corporativo/servicio-al-cliente | J15: https://www.bci.cl/corporativo/politicas-y-normas/politicas-de-privacidad | K15: Correo | M15: =IF(L15="","",WORKDAY(L15,2,Feriados!$A$2:$A$60)) | Q15: =IF(O15="","",WORKDAY(O15,7,Feriados!$A$2:$A$60)) | T15: =IF(AND(L15="",O15=""),"Por enviar",IF(R15="Sí",IF(S15="","Reportar incumplimiento","Incumplimiento reportado"),IF(AND(Q15<>"",TODAY()>Q15),"Plazo vencido – verificar",IF(AND(M15<>"",TODAY()>M15,N15<>"Sí"),"Correo sin respuesta","En plazo"))))
A16: 15 | B16: Scotiabank Chile | C16: Banca | D16: Banco Scotiabank | E16: 97.018.000-1 | F16: consultasprivacidad@contacto.scotiabank.cl | H16: Customer may ask the bank at any time to stop using their information for promotional purposes (Privacidad y Cookies page); no specific channel given. Email above is stated for general privacy-policy questions, not explicitly for ARCO requests. | I16: Centro de Experiencia 600 600 1100; branches | J16: https://www.scotiabankchile.cl/Personas/politica-de-privacidad | K16: Correo | M16: =IF(L16="","",WORKDAY(L16,2,Feriados!$A$2:$A$60)) | Q16: =IF(O16="","",WORKDAY(O16,7,Feriados!$A$2:$A$60)) | T16: =IF(AND(L16="",O16=""),"Por enviar",IF(R16="Sí",IF(S16="","Reportar incumplimiento","Incumplimiento reportado"),IF(AND(Q16<>"",TODAY()>Q16),"Plazo vencido – verificar",IF(AND(M16<>"",TODAY()>M16,N16<>"Sí"),"Correo sin respuesta","En plazo"))))
A17: 16 | B17: Itaú Chile | C17: Banca | D17: Banco Itaú Chile | E17: 97.023.000-9 | F17: oficialprotecciondedatos@itau.cl | H17: No specific marketing opt-out described; rights requests (incl. oposición) must be submitted in writing to oficialprotecciondedatos@itau.cl. | J17: https://www.itau.cl/personas/terminos-de-uso-y-politicas-de-privacidad | K17: Correo | M17: =IF(L17="","",WORKDAY(L17,2,Feriados!$A$2:$A$60)) | Q17: =IF(O17="","",WORKDAY(O17,7,Feriados!$A$2:$A$60)) | T17: =IF(AND(L17="",O17=""),"Por enviar",IF(R17="Sí",IF(S17="","Reportar incumplimiento","Incumplimiento reportado"),IF(AND(Q17<>"",TODAY()>Q17),"Plazo vencido – verificar",IF(AND(M17<>"",TODAY()>M17,N17<>"Sí"),"Correo sin respuesta","En plazo"))))
A18: 17 | B18: Banco BICE | C18: Banca | H18: Policy states the titular may express at any time their wish not to authorize use of their personal data; no specific channel given. | I18: Formulario de contacto, Servicio al cliente: https://banco.bice.cl/personas/servicio-al-cliente | J18: https://banco.bice.cl/personas/politica-de-privacidad | K18: Canal alternativo | M18: =IF(L18="","",WORKDAY(L18,2,Feriados!$A$2:$A$60)) | Q18: =IF(O18="","",WORKDAY(O18,7,Feriados!$A$2:$A$60)) | T18: =IF(AND(L18="",O18=""),"Por enviar",IF(R18="Sí",IF(S18="","Reportar incumplimiento","Incumplimiento reportado"),IF(AND(Q18<>"",TODAY()>Q18),"Plazo vencido – verificar",IF(AND(M18<>"",TODAY()>M18,N18<>"Sí"),"Correo sin respuesta","En plazo"))))
A19: 18 | B19: Banco Security | C19: Banca | I19: Servicio Atención Clientes Security +56 2 2584 4060; Solicitud de contacto: https://personas.bancosecurity.cl/servicio-al-cliente/solicitud-de-contacto. Note: privacy page has a contact email in section 'VII. Contacto' but it is Cloudflare-obfuscated and could not be read; page also states 'Banco Security es una marca de Banco BICE'. | J19: https://personas.bancosecurity.cl/informacion-al-cliente/politica-de-privacidad | K19: Canal alternativo | M19: =IF(L19="","",WORKDAY(L19,2,Feriados!$A$2:$A$60)) | Q19: =IF(O19="","",WORKDAY(O19,7,Feriados!$A$2:$A$60)) | T19: =IF(AND(L19="",O19=""),"Por enviar",IF(R19="Sí",IF(S19="","Reportar incumplimiento","Incumplimiento reportado"),IF(AND(Q19<>"",TODAY()>Q19),"Plazo vencido – verificar",IF(AND(M19<>"",TODAY()>M19,N19<>"Sí"),"Correo sin respuesta","En plazo"))))
A20: 19 | B20: Banco Falabella | C20: Banca | F20: datospersonalesbfcl@bancofalabella.cl | H20: Suspensión de comunicaciones promocionales: use the unsubscribe channel in the communication itself, or the channels provided by the Company or SERNAC. Rights also exercisable via forms in the Company's digital channels or in person at branches. | I20: WhatsApp +56 2 2390 6000; https://www.bancofalabella.cl/ayuda-contacto | J20: https://www.bancofalabella.cl/politicas-privacidad | K20: Correo | M20: =IF(L20="","",WORKDAY(L20,2,Feriados!$A$2:$A$60)) | Q20: =IF(O20="","",WORKDAY(O20,7,Feriados!$A$2:$A$60)) | T20: =IF(AND(L20="",O20=""),"Por enviar",IF(R20="Sí",IF(S20="","Reportar incumplimiento","Incumplimiento reportado"),IF(AND(Q20<>"",TODAY()>Q20),"Plazo vencido – verificar",IF(AND(M20<>"",TODAY()>M20,N20<>"Sí"),"Correo sin respuesta","En plazo"))))
A21: 20 | B21: Banco Ripley | C21: Banca | D21: Banco Ripley | E21: 97.947.000-2 | H21: Use the 'canales de desuscripción establecidos en el propio mensaje', or channels established by the Company or SERNAC. | I21: Teléfono / WhatsApp +56 2 2768 9200 (lun-sáb 9:00-21:00; dom y festivos 11:00-20:00); sucursales | J21: https://www.bancoripley.cl/pdf/politica-de-privacidad-banco-y-filiales.pdf | K21: Canal alternativo | M21: =IF(L21="","",WORKDAY(L21,2,Feriados!$A$2:$A$60)) | Q21: =IF(O21="","",WORKDAY(O21,7,Feriados!$A$2:$A$60)) | T21: =IF(AND(L21="",O21=""),"Por enviar",IF(R21="Sí",IF(S21="","Reportar incumplimiento","Incumplimiento reportado"),IF(AND(Q21<>"",TODAY()>Q21),"Plazo vencido – verificar",IF(AND(M21<>"",TODAY()>M21,N21<>"Sí"),"Correo sin respuesta","En plazo"))))
A22: 21 | B22: CMR Falabella (Promotora CMR Falabella) | C22: Retail / tarjetas | D22: Promotora CMR Falabella S.A. | E22: 90.743.000-6 | F22: datospersonalesbfcl@bancofalabella.cl | H22: Banco Falabella privacy policy (covers filial Promotora CMR Falabella): use the unsubscribe channel in each message, or the channels the company or SERNAC provide (e.g. SERNAC 'No Molestar'). | I22: WhatsApp +56 2 2390 6000 (the ARCO channel named in the Banco Falabella y filiales privacy policy) | J22: https://www.cmrpuntos.cl/como-cuidamos-tus-datos | K22: Correo | M22: =IF(L22="","",WORKDAY(L22,2,Feriados!$A$2:$A$60)) | Q22: =IF(O22="","",WORKDAY(O22,7,Feriados!$A$2:$A$60)) | T22: =IF(AND(L22="",O22=""),"Por enviar",IF(R22="Sí",IF(S22="","Reportar incumplimiento","Incumplimiento reportado"),IF(AND(Q22<>"",TODAY()>Q22),"Plazo vencido – verificar",IF(AND(M22<>"",TODAY()>M22,N22<>"Sí"),"Correo sin respuesta","En plazo"))))
A23: 22 | B23: Tarjeta Cencosud Scotiabank | C23: Retail / tarjetas | D23: CAT Administradora de Tarjetas S.A. | E23: 99.500.840-8 | F23: gestionatusdatos@cencosudscotiabank.cl | H23: The declaration says a request to stop promotional messages sent electronically needs no justification and is handled within 3 business days. It names no dedicated channel. | I23: ARCO requests in person at any Cencosud Scotiabank financial branch, with ID (per the declaration). Customer service 600 450 5000 (landline) / 2 2604 5910 (mobile). | J23: https://staticresourcesfiles.blob.core.windows.net/content/web/static/906860754575773-6838258899856127-declaracion_de_privacidad_y_tratamiento_de_datos_personales_cat.pdf | K23: Correo | M23: =IF(L23="","",WORKDAY(L23,2,Feriados!$A$2:$A$60)) | Q23: =IF(O23="","",WORKDAY(O23,7,Feriados!$A$2:$A$60)) | T23: =IF(AND(L23="",O23=""),"Por enviar",IF(R23="Sí",IF(S23="","Reportar incumplimiento","Incumplimiento reportado"),IF(AND(Q23<>"",TODAY()>Q23),"Plazo vencido – verificar",IF(AND(M23<>"",TODAY()>M23,N23<>"Sí"),"Correo sin respuesta","En plazo"))))
A24: 23 | B24: Tarjeta Ripley (CAR S.A.) | C24: Retail / tarjetas | D24: CAR S.A. | E24: 83.187.800-2 | H24: Use the unsubscribe channel in the message itself, or the channels the company or SERNAC provide. | I24: Phone +56 2 2768 9200 or WhatsApp to the same number (Mon-Sat 09:00-21:00, Sun/holidays 11:00-20:00); this is the ARCO channel named in the policy. | J24: https://www.bancoripley.cl/pdf/politica-de-privacidad-banco-y-filiales.pdf | K24: Canal alternativo | M24: =IF(L24="","",WORKDAY(L24,2,Feriados!$A$2:$A$60)) | Q24: =IF(O24="","",WORKDAY(O24,7,Feriados!$A$2:$A$60)) | T24: =IF(AND(L24="",O24=""),"Por enviar",IF(R24="Sí",IF(S24="","Reportar incumplimiento","Incumplimiento reportado"),IF(AND(Q24<>"",TODAY()>Q24),"Plazo vencido – verificar",IF(AND(M24<>"",TODAY()>M24,N24<>"Sí"),"Correo sin respuesta","En plazo"))))
A25: 24 | B25: Tarjeta Lider Bci (Servicios Financieros Walmart/Bci) | C25: Retail / tarjetas | D25: Servicios Financieros y Administración de Créditos Comerciales S.A. (issuer); Administradora de Tarjetas Servicios Financieros Limitada (RUT 96.867.130-8, administrator) | E25: 77.085.380-K | F25: servicioalcliente@ssff.cl | H25: SMS: in the SMS itself. Email: in the email itself. Phone calls: by phone. Postal mail: call 600 600 5757. You can also call 600 600 5757 to be excluded from any or all channels. The policy says it honors the SERNAC 'No Molestar' list. | I25: 600 600 5757. The same policy also lists servicioalcliente@liderbci.cl as the 'Gerencia de Clientes' contact for the database controller. | J25: https://www.liderbci.cl/politica-de-privacidad | K25: Correo | M25: =IF(L25="","",WORKDAY(L25,2,Feriados!$A$2:$A$60)) | Q25: =IF(O25="","",WORKDAY(O25,7,Feriados!$A$2:$A$60)) | T25: =IF(AND(L25="",O25=""),"Por enviar",IF(R25="Sí",IF(S25="","Reportar incumplimiento","Incumplimiento reportado"),IF(AND(Q25<>"",TODAY()>Q25),"Plazo vencido – verificar",IF(AND(M25<>"",TODAY()>M25,N25<>"Sí"),"Correo sin respuesta","En plazo"))))
A26: 25 | B26: Tarjeta La Polar | C26: Retail / tarjetas | D26: abc (antes Empresas La Polar S.A.) | H26: The terms say you have the right to object to processing for marketing purposes. No specific channel is given beyond in-store or customer service. | I26: Data rights in person at stores or through customer service (per abc.cl T&C sec. 12). Tarjeta abc/La Polar customer service: 600 830 2222, WhatsApp +56 9 9885 7500. | J26: https://www.abc.cl/terminos-y-condiciones.html | K26: Canal alternativo | M26: =IF(L26="","",WORKDAY(L26,2,Feriados!$A$2:$A$60)) | Q26: =IF(O26="","",WORKDAY(O26,7,Feriados!$A$2:$A$60)) | T26: =IF(AND(L26="",O26=""),"Por enviar",IF(R26="Sí",IF(S26="","Reportar incumplimiento","Incumplimiento reportado"),IF(AND(Q26<>"",TODAY()>Q26),"Plazo vencido – verificar",IF(AND(M26<>"",TODAY()>M26,N26<>"Sí"),"Correo sin respuesta","En plazo"))))
A27: 26 | B27: Tarjeta Hites | C27: Retail / tarjetas | D27: Inversiones y Tarjetas S.A. | E27: 85.325.100-3 | H27: Every promotional message must include an expedited way to request suspension. Consent can be revoked 'a través de los canales dispuestos por la empresa'. | I27: Changes to personal data go through the 'departamento de relaciones comerciales de las Tiendas Hites' (in store). Hites contact center: 600 550 6000. | J27: https://tarjetahites.cl/politicas-privacidad-app/ | K27: Canal alternativo | M27: =IF(L27="","",WORKDAY(L27,2,Feriados!$A$2:$A$60)) | Q27: =IF(O27="","",WORKDAY(O27,7,Feriados!$A$2:$A$60)) | T27: =IF(AND(L27="",O27=""),"Por enviar",IF(R27="Sí",IF(S27="","Reportar incumplimiento","Incumplimiento reportado"),IF(AND(Q27<>"",TODAY()>Q27),"Plazo vencido – verificar",IF(AND(M27<>"",TODAY()>M27,N27<>"Sí"),"Correo sin respuesta","En plazo"))))
A28: 27 | B28: Tarjeta abcvisa / Solventa (abcdin) | C28: Retail / tarjetas | H28: The abc.cl terms say you have the right to object to processing for marketing purposes. No dedicated channel is given. | I28: Data rights in person at abc stores or through customer service (abc.cl T&C sec. 12). Tarjeta abc customer service: 600 830 2222, WhatsApp +56 9 9885 7500. | J28: https://www.abc.cl/terminos-y-condiciones.html | K28: Canal alternativo | M28: =IF(L28="","",WORKDAY(L28,2,Feriados!$A$2:$A$60)) | Q28: =IF(O28="","",WORKDAY(O28,7,Feriados!$A$2:$A$60)) | T28: =IF(AND(L28="",O28=""),"Por enviar",IF(R28="Sí",IF(S28="","Reportar incumplimiento","Incumplimiento reportado"),IF(AND(Q28<>"",TODAY()>Q28),"Plazo vencido – verificar",IF(AND(M28<>"",TODAY()>M28,N28<>"Sí"),"Correo sin respuesta","En plazo"))))
A29: 28 | B29: Falabella retail (falabella.com) | C29: Retail / tarjetas | D29: Falabella Retail S.A. | E29: 77.261.280-K | F29: tusdatospersonales@falabella.cl | H29: Sec. 13: use the unsubscribe channel included in the communication, or the channels the companies or SERNAC provide. Members of Mi Cuenta / loyalty programs can also revoke consent. | I29: The forms 'dispuestos en todos los Canales Digitales de la Compañía' (no specific URL given). | J29: https://www.falabella.com/falabella-cl/page/politica-privacidad-falabella-retail | K29: Correo | M29: =IF(L29="","",WORKDAY(L29,2,Feriados!$A$2:$A$60)) | Q29: =IF(O29="","",WORKDAY(O29,7,Feriados!$A$2:$A$60)) | T29: =IF(AND(L29="",O29=""),"Por enviar",IF(R29="Sí",IF(S29="","Reportar incumplimiento","Incumplimiento reportado"),IF(AND(Q29<>"",TODAY()>Q29),"Plazo vencido – verificar",IF(AND(M29<>"",TODAY()>M29,N29<>"Sí"),"Correo sin respuesta","En plazo"))))
A30: 29 | B30: Paris (Cencosud retail) | C30: Retail / tarjetas | D30: Cencosud Retail S.A. | F30: datospersonales@cencosud.cl | H30: Send a written request to datospersonales@cencosud.cl asking to stop receiving advertising communications. | I30: Postal address in the policy: Av. Kennedy 9001, piso 4, Las Condes. | J30: https://www.paris.cl/informaciones-legales/politica-privacidad-de-datos/ | K30: Correo | M30: =IF(L30="","",WORKDAY(L30,2,Feriados!$A$2:$A$60)) | Q30: =IF(O30="","",WORKDAY(O30,7,Feriados!$A$2:$A$60)) | T30: =IF(AND(L30="",O30=""),"Por enviar",IF(R30="Sí",IF(S30="","Reportar incumplimiento","Incumplimiento reportado"),IF(AND(Q30<>"",TODAY()>Q30),"Plazo vencido – verificar",IF(AND(M30<>"",TODAY()>M30,N30<>"Sí"),"Correo sin respuesta","En plazo"))))
A31: 30 | B31: Lider / Walmart Chile | C31: Retail / tarjetas | F31: servicioalcliente@lider.cl | H31: Update communication preferences in your lider.cl account, or by email to servicioalcliente@lider.cl (the privacy policy names this channel). | I31: Call Center 600 400 9000; WhatsApp +56 9 5721 1492. | J31: https://www.lider.cl/ayuda/articulo/politicas-de-privacidad/b7331045956d4b5298f1436343afebdd | K31: Correo | M31: =IF(L31="","",WORKDAY(L31,2,Feriados!$A$2:$A$60)) | Q31: =IF(O31="","",WORKDAY(O31,7,Feriados!$A$2:$A$60)) | T31: =IF(AND(L31="",O31=""),"Por enviar",IF(R31="Sí",IF(S31="","Reportar incumplimiento","Incumplimiento reportado"),IF(AND(Q31<>"",TODAY()>Q31),"Plazo vencido – verificar",IF(AND(M31<>"",TODAY()>M31,N31<>"Sí"),"Correo sin respuesta","En plazo"))))
A32: 31 | B32: BNP Paribas Cardif Chile | C32: Seguros | D32: BNP Paribas Cardif Seguros de Vida S.A. (Chile) y BNP Paribas Cardif Seguros Generales S.A. | H32: El Aviso de Privacidad reconoce el derecho a oponerse al tratamiento con fines de prospección comercial (ofertas por teléfono y correo 'salvo que se oponga'); solicitudes de derechos por escrito a Avenida Vitacura N° 2670, piso 9, Las Condes, Región Metropolitana, o 'en nuestra página web cuando proceda'. | I32: servicio.cliente@cardif.cl (vida, hogar, desempleo u otros) / soluciones@cardif.cl (automotriz); tel. 800 362 100; contacto: https://bnpparibascardif.cl/contacto/ | J32: https://bnpparibascardif.cl/wp-content/uploads/sites/15/2024/12/Aviso-de-privacidad.pdf | K32: Canal alternativo | M32: =IF(L32="","",WORKDAY(L32,2,Feriados!$A$2:$A$60)) | Q32: =IF(O32="","",WORKDAY(O32,7,Feriados!$A$2:$A$60)) | T32: =IF(AND(L32="",O32=""),"Por enviar",IF(R32="Sí",IF(S32="","Reportar incumplimiento","Incumplimiento reportado"),IF(AND(Q32<>"",TODAY()>Q32),"Plazo vencido – verificar",IF(AND(M32<>"",TODAY()>M32,N32<>"Sí"),"Correo sin respuesta","En plazo"))))
A33: 32 | B33: MetLife Chile | C33: Seguros | D33: MetLife Chile Seguros de Vida S.A. | F33: derechosarcc@metlife.cl | G33: https://w3.metlife.cl/content/dam/metlifecom/cl/pdfs/derechos-arcc/FORMULARIO-DE-SOLICITUD-ARCC-WEB.pdf | H33: Revocar o modificar consentimiento de uso de datos escribiendo a dpo@metlife.cl (página Ley de Protección de Datos: https://w3.metlife.cl/ley-de-proteccion-de-datos/). | I33: Call center 600 390 3000; WhatsApp +56 9 9808 1155; Av. Apoquindo 2730, Piso 18, Las Condes | J33: https://w3.metlife.cl/derechos-arcc | K33: Correo | M33: =IF(L33="","",WORKDAY(L33,2,Feriados!$A$2:$A$60)) | Q33: =IF(O33="","",WORKDAY(O33,7,Feriados!$A$2:$A$60)) | T33: =IF(AND(L33="",O33=""),"Por enviar",IF(R33="Sí",IF(S33="","Reportar incumplimiento","Incumplimiento reportado"),IF(AND(Q33<>"",TODAY()>Q33),"Plazo vencido – verificar",IF(AND(M33<>"",TODAY()>M33,N33<>"Sí"),"Correo sin respuesta","En plazo"))))
A34: 33 | B34: BCI Seguros | C34: Seguros | G34: https://privacyportal-br.onetrust.com/webform/34d4a9e1-b824-41bf-b78b-1bd88cabf2d6/bd522870-69b6-4460-8121-e766f09d00d4 | H34: Los e-mails de promoción de ofertas y encuestas siempre incluyen un link para solicitar no recibir más ese tipo de e-mail. Modificación de datos llamando al 600 6000 292. | I34: Tel. 600 6000 292; Consultas y reclamos: https://www.bciseguros.cl/especiales/informacion-sobre-atencion-de-clientes-y-presentacion-de-consultas-y-reclamos/ | J34: https://www.bciseguros.cl/especiales/politicas-privacidad-uso-de-los-datos/ | K34: Formulario web | M34: =IF(L34="","",WORKDAY(L34,2,Feriados!$A$2:$A$60)) | Q34: =IF(O34="","",WORKDAY(O34,7,Feriados!$A$2:$A$60)) | T34: =IF(AND(L34="",O34=""),"Por enviar",IF(R34="Sí",IF(S34="","Reportar incumplimiento","Incumplimiento reportado"),IF(AND(Q34<>"",TODAY()>Q34),"Plazo vencido – verificar",IF(AND(M34<>"",TODAY()>M34,N34<>"Sí"),"Correo sin respuesta","En plazo"))))
A35: 34 | B35: Consorcio (Seguros) | C35: Seguros | D35: Grupo Consorcio Financiero S.A. | E35: 79619200 - 3 | F35: privacidad@consorcio.cl | I35: Avenida El Bosque Sur 180 piso 3, Las Condes, Santiago (domicilio del responsable) | J35: https://sitio.consorcio.cl/comunicados/politica-de-privacidad | K35: Correo | M35: =IF(L35="","",WORKDAY(L35,2,Feriados!$A$2:$A$60)) | Q35: =IF(O35="","",WORKDAY(O35,7,Feriados!$A$2:$A$60)) | T35: =IF(AND(L35="",O35=""),"Por enviar",IF(R35="Sí",IF(S35="","Reportar incumplimiento","Incumplimiento reportado"),IF(AND(Q35<>"",TODAY()>Q35),"Plazo vencido – verificar",IF(AND(M35<>"",TODAY()>M35,N35<>"Sí"),"Correo sin respuesta","En plazo"))))
A36: 35 | B36: Zurich Chile | C36: Seguros | D36: Zurich Chile Seguros de Vida S.A.; Zurich Chile Seguros Generales S.A.; Zurich Chile Asset Management Administradora General de Fondos S.A. | F36: clz.oficinadeprivacidadchile@zurich.com | H36: Derecho de oposición al tratamiento por interés legítimo (contacto) y revocación del consentimiento por solicitud escrita al mismo correo de la Oficina de Privacidad. | I36: Tel. 600 600 9090; WhatsApp +56 9 8790 2551; formulario https://www.zurich.cl/conocenos/contacto | J36: https://www.zurich.cl/conocenos/politicas-de-privacidad | K36: Correo | M36: =IF(L36="","",WORKDAY(L36,2,Feriados!$A$2:$A$60)) | Q36: =IF(O36="","",WORKDAY(O36,7,Feriados!$A$2:$A$60)) | T36: =IF(AND(L36="",O36=""),"Por enviar",IF(R36="Sí",IF(S36="","Reportar incumplimiento","Incumplimiento reportado"),IF(AND(Q36<>"",TODAY()>Q36),"Plazo vencido – verificar",IF(AND(M36<>"",TODAY()>M36,N36<>"Sí"),"Correo sin respuesta","En plazo"))))
A37: 36 | B37: Chubb Chile | C37: Seguros | F37: protecciondedatoschile@chubb.com | I37: Clientes.Chile@Chubb.com (indicado en la Política de Privacidad para acceso/corrección); Presidente Riesco 5435, piso 7, Las Condes; formulario https://www.chubb.com/cl-es/contactanos/contactanos.html | J37: https://www.chubb.com/cl-es/bases-legales/aviso-de-proteccion-de-datos.html | K37: Correo | M37: =IF(L37="","",WORKDAY(L37,2,Feriados!$A$2:$A$60)) | Q37: =IF(O37="","",WORKDAY(O37,7,Feriados!$A$2:$A$60)) | T37: =IF(AND(L37="",O37=""),"Por enviar",IF(R37="Sí",IF(S37="","Reportar incumplimiento","Incumplimiento reportado"),IF(AND(Q37<>"",TODAY()>Q37),"Plazo vencido – verificar",IF(AND(M37<>"",TODAY()>M37,N37<>"Sí"),"Correo sin respuesta","En plazo"))))
A38: 37 | B38: HDI Seguros Chile | C38: Seguros | I38: Tel. 600 600 60 10; WhatsApp +56 9 7753 0532; Mi HDI Virtual (https://ww2.hdi.cl/ingresar) opción 'Ingreso de reclamos'; Av. Manquehue Norte 160, piso 19, Las Condes | J38: https://www.hdi.cl/informacion-util | K38: Canal alternativo | M38: =IF(L38="","",WORKDAY(L38,2,Feriados!$A$2:$A$60)) | Q38: =IF(O38="","",WORKDAY(O38,7,Feriados!$A$2:$A$60)) | T38: =IF(AND(L38="",O38=""),"Por enviar",IF(R38="Sí",IF(S38="","Reportar incumplimiento","Incumplimiento reportado"),IF(AND(Q38<>"",TODAY()>Q38),"Plazo vencido – verificar",IF(AND(M38<>"",TODAY()>M38,N38<>"Sí"),"Correo sin respuesta","En plazo"))))
A39: 38 | B39: Mapfre Chile | C39: Seguros | D39: Mapfre Compañía de Seguros Generales de Chile S.A. y Mapfre Compañía de Seguros de Vida de Chile S.A. | F39: dpo@mapfre.cl | H39: Comunicaciones comerciales basadas en consentimiento; se puede revocar el consentimiento en cualquier momento mediante comunicación escrita dirigida a Mapfre Chile. | I39: Contact Center 600 700 4000; Isidora Goyenechea 3520, Las Condes; formulario https://mel.mapfre.cl/cl/portal/servicios/contactenos/ | J39: https://www.mapfre.cl/privacidad/ | K39: Correo | M39: =IF(L39="","",WORKDAY(L39,2,Feriados!$A$2:$A$60)) | Q39: =IF(O39="","",WORKDAY(O39,7,Feriados!$A$2:$A$60)) | T39: =IF(AND(L39="",O39=""),"Por enviar",IF(R39="Sí",IF(S39="","Reportar incumplimiento","Incumplimiento reportado"),IF(AND(Q39<>"",TODAY()>Q39),"Plazo vencido – verificar",IF(AND(M39<>"",TODAY()>M39,N39<>"Sí"),"Correo sin respuesta","En plazo"))))
A40: 39 | B40: AFP Modelo | C40: AFP | D40: AFP Modelo S.A. | I40: Centro de Contacto / sucursales: https://nueva.afpmodelo.cl/centro-contacto (número no legible en la captura del sitio) | J40: https://nueva.afpmodelo.cl/Politicas/ | K40: Canal alternativo | M40: =IF(L40="","",WORKDAY(L40,2,Feriados!$A$2:$A$60)) | Q40: =IF(O40="","",WORKDAY(O40,7,Feriados!$A$2:$A$60)) | T40: =IF(AND(L40="",O40=""),"Por enviar",IF(R40="Sí",IF(S40="","Reportar incumplimiento","Incumplimiento reportado"),IF(AND(Q40<>"",TODAY()>Q40),"Plazo vencido – verificar",IF(AND(M40<>"",TODAY()>M40,N40<>"Sí"),"Correo sin respuesta","En plazo"))))
...

Sheet Feriados
A1: Fecha | B1: Feriado | D1: Fuente 2027: calendariochile.com (feriados nacionales). Agrega feriados nuevos al final de la lista, dentro del rango A2:A60.
A2: 46326 | B2: Día de las Iglesias Evangélicas y Protestantes
A3: 46327 | B3: Día de Todos los Santos
A4: 46364 | B4: Inmaculada Concepción
A5: 46381 | B5: Navidad
A6: 46388 | B6: Año Nuevo
A7: 46472 | B7: Viernes Santo
A8: 46473 | B8: Sábado Santo
A9: 46508 | B9: Día del Trabajo
A10: 46528 | B10: Glorias Navales
A11: 46558 | B11: Día Nacional de los Pueblos Indígenas
A12: 46566 | B12: San Pedro y San Pablo
A13: 46584 | B13: Virgen del Carmen
... A21: 46746 | B21: Navidad
